Workbook

Sheet Worksheet
A1: NRO | B1: DNI | C1: APELLIDOS Y NOMBRES COMPLETO | D1: CORREO | E1: CELULAR | F1: GRADO | G1: PROGRAMA | H1: NOTA FINAL | I1: SITUACIÓN
A2: NRO | B2: DNI | C2: APELLIDOS Y NOMBRES COMPLETO | D2: CORREO | E2: CELULAR | F2: GRADO | G2: PROGRAMA | H2: NOTA FINAL | I2: SITUACIÓN
A3: 9 | B3: 75363208 | C3: LLAMO DIAZ NELSON JOSUE | D3: nejlld25@gmail.com | E3: 955850651 | F3: MAESTRIA | G3: Ciencias con mención en Ingeniería Hidráulica | H3: 80.5 | I3: ALCANZÓ VACANTE
A4: 18 | B4: 44666269 | C4: SILVA DELGADO GHIERALD ELOY | D4: silvaagricola0406@gmail.com | E4: 926186587 | F4: MAESTRIA | G4: Ciencias con mención en Ingeniería Hidráulica | H4: 74.5 | I4: ALCANZÓ VACANTE
A5: 3 | B5: 71491689 | C5: CIEZA HERRERA IVAN MARCELO | D5: ivanciencias13@gmail.com | E5: 968750910 | F5: MAESTRIA | G5: Ciencias con mención en Ingeniería Hidráulica | H5: 74 | I5: ALCANZÓ VACANTE
A6: 17 | B6: 73462669 | C6: SAUCEDO LINARES CRISTIAN YOMAR | D6: cristiansaucedolinares10@gmail.com | E6: 975609988 | F6: MAESTRIA | G6: Ciencias con mención en Ingeniería Hidráulica | H6: 74 | I6: ALCANZÓ VACANTE
A7: 1 | B7: 71396806 | C7: ARBOLEDA IMAN JUAN MANUEL | D7: juanarboledai1996@gmail.com | E7: 972026173 | F7: MAESTRIA | G7: Ciencias con mención en Ingeniería Hidráulica | H7: 73.5 | I7: ALCANZÓ VACANTE
A8: 2 | B8: 43111414 | C8: AREVALO CORONEL RAUL JOEL | D8: rauljac86@outlook.com | E8: 939737207 | F8: MAESTRIA | G8: Ciencias con mención en Ingeniería Hidráulica | H8: 72.5 | I8: ALCANZÓ VACANTE
A9: 5 | B9: 60258953 | C9: GUEVARA PORTILLO FRANCO DAVID | D9: francod.gp@gmail.com | E9: 990453660 | F9: MAESTRIA | G9: Ciencias con mención en Ingeniería Hidráulica | H9: 72.5 | I9: ALCANZÓ VACANTE
A10: 12 | B10: 73025102 | C10: OJEDA CAPUÑAY RENZO PAOLO | D10: renzo_ojeda_0304@outlook.com | E10: 963584802 | F10: MAESTRIA | G10: Ciencias con mención en Ingeniería Hidráulica | H10: 72.5 | I10: ALCANZÓ VACANTE
A11: 7 | B11: 75720372 | C11: HUAYTALLA YARANGA JOSE LUIS | D11: jose.huaytalla21@gmail.com | E11: 941361826 | F11: MAESTRIA | G11: Ciencias con mención en Ingeniería Hidráulica | H11: 72 | I11: ALCANZÓ VACANTE
A12: 15 | B12: 46135037 | C12: SAAVEDRA RUIZ AQUILES | D12: aquiles_sr4@hotmail.com | E12: 918313510 | F12: MAESTRIA | G12: Ciencias con mención en Ingeniería Hidráulica | H12: 70 | I12: ALCANZÓ VACANTE
A13: 10 | B13: 48199611 | C13: MANAYAY MANAYAY JOSELITO | D13: jmanayaym@hotmail.com | E13: 925882492 | F13: MAESTRIA | G13: Ciencias con mención en Ingeniería Hidráulica | H13: 68.5 | I13: ALCANZÓ VACANTE
A14: 4 | B14: 73514125 | C14: DE LA CRUZ DE LA CRUZ LUIS ARMANDO | D14: luisdelacruz1409@gmail.com | E14: 973854830 | F14: MAESTRIA | G14: Ciencias con mención en Ingeniería Hidráulica | H14: 67.5 | I14: ALCANZÓ VACANTE
... A183: 2 | B183: 73262781 | C183: CHINCHAYAN BARRENECHEA MARIO JESUS | D183: mariojcb1910@gmail.com | E183: 910201305 | F183: MAESTRIA | G183: Ciencias de la Educación con mención en Docencia y Gestión Universitaria | H183: 71.9 | I183: ALCANZÓ VACANTE
A184: 3 | B184: 03886801 | C184: VELASQUEZ SAAVEDRA ROGER JAVIER | D184: rogervelasquezsaavedra@gmail.com | E184: 947495718 | F184: MAESTRIA | G184: Ciencias de la Educación con mención en Docencia y Gestión Universitaria | H184: 71.9 | I184: ALCANZÓ VACANTE
A185: 4 | B185: 47248891 | C185: SAAVEDRA AGUILAR RAUL CRISTHIAN | D185: raulcristhians@gmail.com | E185: 940115835 | F185: MAESTRIA | G185: Ciencias de la Educación con mención en Docencia y Gestión Universitaria | H185: 71 | I185: ALCANZÓ VACANTE
A186: 5 | B186: 43984489 | C186: ASALDE YUPTON MIGUEL ANGEL | D186: masalde@unprg.edu.pe | E186: 928228502 | F186: MAESTRIA | G186: Ciencias de la Educación con mención en Docencia y Gestión Universitaria | H186: 70.5 | I186: ALCANZÓ VACANTE
A187: 6 | B187: 71077059 | C187: CHUMIOQUE CHARCAPE MYRIAN JESUS | D187: miriam04leo@gmail.com | E187: 936794282 | F187: MAESTRIA | G187: Ciencias de la Educación con mención en Docencia y Gestión Universitaria | H187: 69.9 | I187: ALCANZÓ VACANTE
A188: 7 | B188: 72023455 | C188: ADRIANZEN FLORES JEAN MARCOS | D188: jeanmarcosadrianzenflores@gmail.com | E188: 926104720 | F188: MAESTRIA | G188: Ciencias de la Educación con mención en Docencia y Gestión Universitaria | H188: 69.1 | I188: ALCANZÓ VACANTE
A189: 8 | B189: 44197041 | C189: ZEÑA SAMPEN JOSE ERNESTO | D189: ernestozena@gmail.com | E189: 966243348 | F189: MAESTRIA | G189: Ciencias de la Educación con mención en Docencia y Gestión Universitaria | H189: 69 | I189: ALCANZÓ VACANTE
A190: 9 | B190: 45401537 | C190: MARCHENA CAICAY FABIOLA MARDELI | D190: fabiomardelly@gmail.com | E190: 943749457 | F190: MAESTRIA | G190: Ciencias de la Educación con mención en Docencia y Gestión Universitaria | H190: 68.5 | I190: ALCANZÓ VACANTE
A191: 10 | B191: 47660655 | C191: RAMIREZ RAMIREZ LEIDY RUTH | D191: leidycomunicaciones20@gmail.com | E191: 969945719 | F191: MAESTRIA | G191: Ciencias de la Educación con mención en Docencia y Gestión Universitaria | H191: 68.5 | I191: ALCANZÓ VACANTE
A192: 11 | B192: 47289823 | C192: IZQUIERDO ZELADA GIANMARCOS | D192: ing.izquierdozeladagianmarcos@gmail.com | E192: 949630670 | F192: MAESTRIA | G192: Ciencias de la Educación con mención en Docencia y Gestión Universitaria | H192: 68.2 | I192: ALCANZÓ VACANTE
A193: 12 | B193: 70473446 | C193: CASTILLO OROZCO JUAN MANUEL | D193: manuco010198@gmail.com | E193: 981228668 | F193: MAESTRIA | G193: Ciencias de la Educación con mención en Docencia y Gestión Universitaria | H193: 68 | I193: ALCANZÓ VACANTE
A194: 13 | B194: 60893958 | C194: GUTIERREZ BALTAZAR LIZETH MARGOTH | D194: liz.got7.miracle@gmail.com | E194: 930738695 | F194: MAESTRIA | G194: Ciencias de la Educación con mención en Docencia y Gestión Universitaria | H194: 68 | I194: ALCANZÓ VACANTE
A195: 14 | B195: 72482012 | C195: SOSA RUBIÑOS MAITE NAYELI DEL MILAGRO | D195: Msosar@unprg.edu.pe | E195: 920737473 | F195: MAESTRIA | G195: Ciencias de la Educación con mención en Docencia y Gestión Universitaria | H195: 68 | I195: ALCANZÓ VACANTE
A196: 15 | B196: 46043232 | C196: VENTURA CARDENAS CELESTE LIZETH | D196: celestelizethventuracardenas@gmail.com | E196: 933961193 | F196: MAESTRIA | G196: Ciencias de la Educación con mención en Docencia y Gestión Universitaria | H196: 67.9 | I196: ALCANZÓ VACANTE
... A220: 39 | B220: 16774611 | C220: DAMIAN ESPINO JULIO EDGAR | D220: jdaviddamian2803@gmail.com | E220: 952809556 | F220: MAESTRIA | G220: Ciencias de la Educación con mención en Docencia y Gestión Universitaria | H220: 55.8 | I220: ALCANZÓ VACANTE
A221: 40 | B221: 02843308 | C221: JIMENEZ LIVIA CRUZALINA | D221: cjimenezl@unprg.edu.pe | E221: 963128554 | F221: MAESTRIA | G221: Ciencias de la Educación con mención en Docencia y Gestión Universitaria | H221: 55.7 | I221: ALCANZÓ VACANTE
A222: 41 | B222: 08385207 | C222: CALVAY ORTIZ MANUEL ANTONIO | D222: ak_1917@hotmail.com | E222: 975618503 | F222: MAESTRIA | G222: Ciencias de la Educación con mención en Docencia y Gestión Universitaria | H222: 55 | I222: ALCANZÓ VACANTE
A223: 42 | B223: 16691936 | C223: SOLANO HURTADO JESSY | D223: jessysolano2017@gmail.com | E223: 979410962 | F223: MAESTRIA | G223: Ciencias de la Educación con mención en Docencia y Gestión Universitaria | H223: 52.8 | I223: ALCANZÓ VACANTE
A224: 43 | B224: 72523216 | C224: CERNA BECERRA YENNIFFER LIONELA | D224: leonelab862@gmail.com | E224: 936244503 | F224: MAESTRIA | G224: Ciencias de la Educación con mención en Docencia y Gestión Universitaria | H224: 52 | I224: ALCANZÓ VACANTE
A225: 44 | B225: 42870365 | C225: MILIAN PEREZ RENE DEL PILAR | D225: rene20milian@gmail.com | E225: 962179687 | F225: MAESTRIA | G225: Ciencias de la Educación con mención en Docencia y Gestión Universitaria | H225: 51 | I225: ALCANZÓ VACANTE
A226: 45 | B226: 70800189 | C226: GONZALES ZAPATA ROSA ESTELA | D226: gonzaleszapatar1@gmail.com | E226: 989562762 | F226: MAESTRIA | G226: Ciencias de la Educación con mención en Docencia y Gestión Universitaria | H226: 3 | I226: NO ALCANZÓ VACANTE
A227: 46 | B227: 76371544 | C227: DIAZ FERNANDEZ ROYNER ADERSON | D227: royneradersondiazfernandez@gmail.com | E227: 945880578 | F227: MAESTRIA | G227: Ciencias de la Educación con mención en Docencia y Gestión Universitaria | H227: 0 | I227: NO ALCANZÓ VACANTE
A228: 1 | B228: 72928145 | C228: VELEZ HUERTAS RICARDO FABRICIO | D228: rvelezh@unprg.edu.pe | E228: 983846148 | F228: MAESTRIA | G228: Ciencias Sociales con mención en Gestión Pública y Gerencia Social | H228: 77.3 | I228: ALCANZÓ VACANTE
A229: 2 | B229: 70840720 | C229: CALMET VILLEGAS CARLOS GUILLERMO | D229: carloscalmet25@gmail.com | E229: 992278663 | F229: MAESTRIA | G229: Ciencias Sociales con mención en Gestión Pública y Gerencia Social | H229: 75.6 | I229: ALCANZÓ VACANTE
A230: 3 | B230: 42062400 | C230: PACHERRES ALCANTARA INGRID OLGA | D230: ipacherresalcantara@gmail.com | E230: 996617036 | F230: MAESTRIA | G230: Ciencias Sociales con mención en Gestión Pública y Gerencia Social | H230: 74 | I230: ALCANZÓ VACANTE
A231: 4 | B231: 45038251 | C231: CUMPA PUICAN JUAN KAROLL | D231: cumpap.juan@gmail.com | E231: 939080978 | F231: MAESTRIA | G231: Ciencias Sociales con mención en Gestión Pública y Gerencia Social | H231: 73.5 | I231: ALCANZÓ VACANTE
...

Sheet INGRESANTES
A1: NRO | B1: TIPO | C1: DNI | D1: APELLIDOS Y NOMBRES COMPLETO | E1: APELLIDOS_NOMBRES | F1: APELLIDO_PAT | G1: APELLIDO_MAT | H1: NOMBRES | I1: CORREO | J1: CORREO_UNPRG | K1: CELULAR | L1: GRADO | M1: PROGRAMA | N1: NOTA FINAL | O1: SITUACIÓN
A2: 1 | B2: AL | C2: 75363208 | D2: LLAMO DIAZ NELSON JOSUE | E2: LLAMO DIAZ, NELSON JOSUE | F2: LLAMO | G2: DIAZ | H2: NELSON JOSUE | I2: nejlld25@gmail.com | J2: @UNPRG.EDU.PE | K2: 955850651 | L2: MAESTRIA | M2: Ciencias con mención en Ingeniería Hidráulica | N2: 80.5 | O2: ALCANZÓ VACANTE
A3: 2 | B3: AL | C3: 44666269 | D3: SILVA DELGADO GHIERALD ELOY | E3: SILVA DELGADO, GHIERALD ELOY | F3: SILVA | G3: DELGADO | H3: GHIERALD ELOY | I3: silvaagricola0406@gmail.com | J3: @UNPRG.EDU.PE | K3: 926186587 | L3: MAESTRIA | M3: Ciencias con mención en Ingeniería Hidráulica | N3: 74.5 | O3: ALCANZÓ VACANTE
A4: 3 | B4: AL | C4: 71491689 | D4: CIEZA HERRERA IVAN MARCELO | E4: CIEZA HERRERA, IVAN MARCELO | F4: CIEZA | G4: HERRERA | H4: IVAN MARCELO | I4: ivanciencias13@gmail.com | J4: @UNPRG.EDU.PE | K4: 968750910 | L4: MAESTRIA | M4: Ciencias con mención en Ingeniería Hidráulica | N4: 74 | O4: ALCANZÓ VACANTE
A5: 4 | B5: AL | C5: 73462669 | D5: SAUCEDO LINARES CRISTIAN YOMAR | E5: SAUCEDO LINARES, CRISTIAN YOMAR | F5: SAUCEDO | G5: LINARES | H5: CRISTIAN YOMAR | I5: cristiansaucedolinares10@gmail.com | J5: @UNPRG.EDU.PE | K5: 975609988 | L5: MAESTRIA | M5: Ciencias con mención en Ingeniería Hidráulica | N5: 74 | O5: ALCANZÓ VACANTE
A6: 5 | B6: AL | C6: 71396806 | D6: ARBOLEDA IMAN JUAN MANUEL | E6: ARBOLEDA IMAN, JUAN MANUEL | F6: ARBOLEDA | G6: IMAN | H6: JUAN MANUEL | I6: juanarboledai1996@gmail.com | J6: @UNPRG.EDU.PE | K6: 972026173 | L6: MAESTRIA | M6: Ciencias con mención en Ingeniería Hidráulica | N6: 73.5 | O6: ALCANZÓ VACANTE
A7: 6 | B7: AL | C7: 43111414 | D7: AREVALO CORONEL RAUL JOEL | E7: AREVALO CORONEL, RAUL JOEL | F7: AREVALO | G7: CORONEL | H7: RAUL JOEL | I7: rauljac86@outlook.com | J7: @UNPRG.EDU.PE | K7: 939737207 | L7: MAESTRIA | M7: Ciencias con mención en Ingeniería Hidráulica | N7: 72.5 | O7: ALCANZÓ VACANTE
A8: 7 | B8: AL | C8: 60258953 | D8: GUEVARA PORTILLO FRANCO DAVID | E8: GUEVARA PORTILLO, FRANCO DAVID | F8: GUEVARA | G8: PORTILLO | H8: FRANCO DAVID | I8: francod.gp@gmail.com | J8: @UNPRG.EDU.PE | K8: 990453660 | L8: MAESTRIA | M8: Ciencias con mención en Ingeniería Hidráulica | N8: 72.5 | O8: ALCANZÓ VACANTE
A9: 8 | B9: AL | C9: 73025102 | D9: OJEDA CAPUÑAY RENZO PAOLO | E9: OJEDA CAPUÑAY, RENZO PAOLO | F9: OJEDA | G9: CAPUÑAY | H9: RENZO PAOLO | I9: renzo_ojeda_0304@outlook.com | J9: @UNPRG.EDU.PE | K9: 963584802 | L9: MAESTRIA | M9: Ciencias con mención en Ingeniería Hidráulica | N9: 72.5 | O9: ALCANZÓ VACANTE
A10: 9 | B10: AL | C10: 75720372 | D10: HUAYTALLA YARANGA JOSE LUIS | E10: HUAYTALLA YARANGA, JOSE LUIS | F10: HUAYTALLA | G10: YARANGA | H10: JOSE LUIS | I10: jose.huaytalla21@gmail.com | J10: @UNPRG.EDU.PE | K10: 941361826 | L10: MAESTRIA | M10: Ciencias con mención en Ingeniería Hidráulica | N10: 72 | O10: ALCANZÓ VACANTE
A11: 10 | B11: AL | C11: 46135037 | D11: SAAVEDRA RUIZ AQUILES | E11: SAAVEDRA RUIZ, AQUILES | F11: SAAVEDRA | G11: RUIZ | H11: AQUILES | I11: aquiles_sr4@hotmail.com | J11: @UNPRG.EDU.PE | K11: 918313510 | L11: MAESTRIA | M11: Ciencias con mención en Ingeniería Hidráulica | N11: 70 | O11: ALCANZÓ VACANTE
A12: 11 | B12: AL | C12: 48199611 | D12: MANAYAY MANAYAY JOSELITO | E12: MANAYAY MANAYAY, JOSELITO | F12: MANAYAY | G12: MANAYAY | H12: JOSELITO | I12: jmanayaym@hotmail.com | J12: @UNPRG.EDU.PE | K12: 925882492 | L12: MAESTRIA | M12: Ciencias con mención en Ingeniería Hidráulica | N12: 68.5 | O12: ALCANZÓ VACANTE
A13: 12 | B13: AL | C13: 73514125 | D13: DE LA CRUZ DE LA CRUZ LUIS ARMANDO | E13: DE LA CRUZ DE LA CRUZ, LUIS ARMANDO | F13: DE LA CRUZ | G13: DE LA CRUZ | H13: LUIS ARMANDO | I13: luisdelacruz1409@gmail.com | J13: @UNPRG.EDU.PE | K13: 973854830 | L13: MAESTRIA | M13: Ciencias con mención en Ingeniería Hidráulica | N13: 67.5 | O13: ALCANZÓ VACANTE
... A168: 167 | B168: AL | C168: 73262781 | D168: CHINCHAYAN BARRENECHEA MARIO JESUS | E168: CHINCHAYAN BARRENECHEA, MARIO JESUS | F168: CHINCHAYAN | G168: BARRENECHEA | H168: MARIO JESUS | I168: mariojcb1910@gmail.com | J168: @UNPRG.EDU.PE | K168: 910201305 | L168: MAESTRIA | M168: Ciencias de la Educación con mención en Docencia y Gestión Universitaria | N168: 71.9 | O168: ALCANZÓ VACANTE
A169: 168 | B169: AL | C169: 03886801 | D169: VELASQUEZ SAAVEDRA ROGER JAVIER | E169: VELASQUEZ SAAVEDRA, ROGER JAVIER | F169: VELASQUEZ | G169: SAAVEDRA | H169: ROGER JAVIER | I169: rogervelasquezsaavedra@gmail.com | J169: @UNPRG.EDU.PE | K169: 947495718 | L169: MAESTRIA | M169: Ciencias de la Educación con mención en Docencia y Gestión Universitaria | N169: 71.9 | O169: ALCANZÓ VACANTE
A170: 169 | B170: AL | C170: 47248891 | D170: SAAVEDRA AGUILAR RAUL CRISTHIAN | E170: SAAVEDRA AGUILAR, RAUL CRISTHIAN | F170: SAAVEDRA | G170: AGUILAR | H170: RAUL CRISTHIAN | I170: raulcristhians@gmail.com | J170: @UNPRG.EDU.PE | K170: 940115835 | L170: MAESTRIA | M170: Ciencias de la Educación con mención en Docencia y Gestión Universitaria | N170: 71 | O170: ALCANZÓ VACANTE
A171: 170 | B171: AL | C171: 43984489 | D171: ASALDE YUPTON MIGUEL ANGEL | E171: ASALDE YUPTON, MIGUEL ANGEL | F171: ASALDE | G171: YUPTON | H171: MIGUEL ANGEL | I171: masalde@unprg.edu.pe | J171: @UNPRG.EDU.PE | K171: 928228502 | L171: MAESTRIA | M171: Ciencias de la Educación con mención en Docencia y Gestión Universitaria | N171: 70.5 | O171: ALCANZÓ VACANTE
A172: 171 | B172: AL | C172: 71077059 | D172: CHUMIOQUE CHARCAPE MYRIAN JESUS | E172: CHUMIOQUE CHARCAPE, MYRIAN JESUS | F172: CHUMIOQUE | G172: CHARCAPE | H172: MYRIAN JESUS | I172: miriam04leo@gmail.com | J172: @UNPRG.EDU.PE | K172: 936794282 | L172: MAESTRIA | M172: Ciencias de la Educación con mención en Docencia y Gestión Universitaria | N172: 69.9 | O172: ALCANZÓ VACANTE
A173: 172 | B173: AL | C173: 72023455 | D173: ADRIANZEN FLORES JEAN MARCOS | E173: ADRIANZEN FLORES, JEAN MARCOS | F173: ADRIANZEN | G173: FLORES | H173: JEAN MARCOS | I173: jeanmarcosadrianzenflores@gmail.com | J173: @UNPRG.EDU.PE | K173: 926104720 | L173: MAESTRIA | M173: Ciencias de la Educación con mención en Docencia y Gestión Universitaria | N173: 69.1 | O173: ALCANZÓ VACANTE
A174: 173 | B174: AL | C174: 44197041 | D174: ZEÑA SAMPEN JOSE ERNESTO | E174: ZEÑA SAMPEN, JOSE ERNESTO | F174: ZEÑA | G174: SAMPEN | H174: JOSE ERNESTO | I174: ernestozena@gmail.com | J174: @UNPRG.EDU.PE | K174: 966243348 | L174: MAESTRIA | M174: Ciencias de la Educación con mención en Docencia y Gestión Universitaria | N174: 69 | O174: ALCANZÓ VACANTE
A175: 174 | B175: AL | C175: 45401537 | D175: MARCHENA CAICAY FABIOLA MARDELI | E175: MARCHENA CAICAY, FABIOLA MARDELI | F175: MARCHENA | G175: CAICAY | H175: FABIOLA MARDELI | I175: fabiomardelly@gmail.com | J175: @UNPRG.EDU.PE | K175: 943749457 | L175: MAESTRIA | M175: Ciencias de la Educación con mención en Docencia y Gestión Universitaria | N175: 68.5 | O175: ALCANZÓ VACANTE
A176: 175 | B176: AL | C176: 47660655 | D176: RAMIREZ RAMIREZ LEIDY RUTH | E176: RAMIREZ RAMIREZ, LEIDY RUTH | F176: RAMIREZ | G176: RAMIREZ | H176: LEIDY RUTH | I176: leidycomunicaciones20@gmail.com | J176: @UNPRG.EDU.PE | K176: 969945719 | L176: MAESTRIA | M176: Ciencias de la Educación con mención en Docencia y Gestión Universitaria | N176: 68.5 | O176: ALCANZÓ VACANTE
A177: 176 | B177: AL | C177: 47289823 | D177: IZQUIERDO ZELADA GIANMARCOS | E177: IZQUIERDO ZELADA, GIANMARCOS | F177: IZQUIERDO | G177: ZELADA | H177: GIANMARCOS | I177: ing.izquierdozeladagianmarcos@gmail.com | J177: @UNPRG.EDU.PE | K177: 949630670 | L177: MAESTRIA | M177: Ciencias de la Educación con mención en Docencia y Gestión Universitaria | N177: 68.2 | O177: ALCANZÓ VACANTE
A178: 177 | B178: AL | C178: 70473446 | D178: CASTILLO OROZCO JUAN MANUEL | E178: CASTILLO OROZCO, JUAN MANUEL | F178: CASTILLO | G178: OROZCO | H178: JUAN MANUEL | I178: manuco010198@gmail.com | J178: @UNPRG.EDU.PE | K178: 981228668 | L178: MAESTRIA | M178: Ciencias de la Educación con mención en Docencia y Gestión Universitaria | N178: 68 | O178: ALCANZÓ VACANTE
A179: 178 | B179: AL | C179: 60893958 | D179: GUTIERREZ BALTAZAR LIZETH MARGOTH | E179: GUTIERREZ BALTAZAR, LIZETH MARGOTH | F179: GUTIERREZ | G179: BALTAZAR | H179: LIZETH MARGOTH | I179: liz.got7.miracle@gmail.com | J179: @UNPRG.EDU.PE | K179: 930738695 | L179: MAESTRIA | M179: Ciencias de la Educación con mención en Docencia y Gestión Universitaria | N179: 68 | O179: ALCANZÓ VACANTE
A180: 179 | B180: AL | C180: 72482012 | D180: SOSA RUBIÑOS MAITE NAYELI DEL MILAGRO | E180: SOSA RUBIÑOS, MAITE NAYELI DEL MILAGRO | F180: SOSA | G180: RUBIÑOS | H180: MAITE NAYELI DEL MILAGRO | I180: Msosar@unprg.edu.pe | J180: @UNPRG.EDU.PE | K180: 920737473 | L180: MAESTRIA | M180: Ciencias de la Educación con mención en Docencia y Gestión Universitaria | N180: 68 | O180: ALCANZÓ VACANTE
A181: 180 | B181: AL | C181: 46043232 | D181: VENTURA CARDENAS CELESTE LIZETH | E181: VENTURA CARDENAS, CELESTE LIZETH | F181: VENTURA | G181: CARDENAS | H181: CELESTE LIZETH | I181: celestelizethventuracardenas@gmail.com | J181: @UNPRG.EDU.PE | K181: 933961193 | L181: MAESTRIA | M181: Ciencias de la Educación con mención en Docencia y Gestión Universitaria | N181: 67.9 | O181: ALCANZÓ VACANTE
... A205: 204 | B205: AL | C205: 16774611 | D205: DAMIAN ESPINO JULIO EDGAR | E205: DAMIAN ESPINO, JULIO EDGAR | F205: DAMIAN | G205: ESPINO | H205: JULIO EDGAR | I205: jdaviddamian2803@gmail.com | J205: @UNPRG.EDU.PE | K205: 952809556 | L205: MAESTRIA | M205: Ciencias de la Educación con mención en Docencia y Gestión Universitaria | N205: 55.8 | O205: ALCANZÓ VACANTE
A206: 205 | B206: AL | C206: 02843308 | D206: JIMENEZ LIVIA CRUZALINA | E206: JIMENEZ LIVIA, CRUZALINA | F206: JIMENEZ | G206: LIVIA | H206: CRUZALINA | I206: cjimenezl@unprg.edu.pe | J206: @UNPRG.EDU.PE | K206: 963128554 | L206: MAESTRIA | M206: Ciencias de la Educación con mención en Docencia y Gestión Universitaria | N206: 55.7 | O206: ALCANZÓ VACANTE
A207: 206 | B207: AL | C207: 08385207 | D207: CALVAY ORTIZ MANUEL ANTONIO | E207: CALVAY ORTIZ, MANUEL ANTONIO | F207: CALVAY | G207: ORTIZ | H207: MANUEL ANTONIO | I207: ak_1917@hotmail.com | J207: @UNPRG.EDU.PE | K207: 975618503 | L207: MAESTRIA | M207: Ciencias de la Educación con mención en Docencia y Gestión Universitaria | N207: 55 | O207: ALCANZÓ VACANTE
A208: 207 | B208: AL | C208: 16691936 | D208: SOLANO HURTADO JESSY | E208: SOLANO HURTADO, JESSY | F208: SOLANO | G208: HURTADO | H208: JESSY | I208: jessysolano2017@gmail.com | J208: @UNPRG.EDU.PE | K208: 979410962 | L208: MAESTRIA | M208: Ciencias de la Educación con mención en Docencia y Gestión Universitaria | N208: 52.8 | O208: ALCANZÓ VACANTE
A209: 208 | B209: AL | C209: 72523216 | D209: CERNA BECERRA YENNIFFER LIONELA | E209: CERNA BECERRA, YENNIFFER LIONELA | F209: CERNA | G209: BECERRA | H209: YENNIFFER LIONELA | I209: leonelab862@gmail.com | J209: @UNPRG.EDU.PE | K209: 936244503 | L209: MAESTRIA | M209: Ciencias de la Educación con mención en Docencia y Gestión Universitaria | N209: 52 | O209: ALCANZÓ VACANTE
A210: 209 | B210: AL | C210: 42870365 | D210: MILIAN PEREZ RENE DEL PILAR | E210: MILIAN PEREZ, RENE DEL PILAR | F210: MILIAN | G210: PEREZ | H210: RENE DEL PILAR | I210: rene20milian@gmail.com | J210: @UNPRG.EDU.PE | K210: 962179687 | L210: MAESTRIA | M210: Ciencias de la Educación con mención en Docencia y Gestión Universitaria | N210: 51 | O210: ALCANZÓ VACANTE
A211: 210 | B211: AL | C211: 72928145 | D211: VELEZ HUERTAS RICARDO FABRICIO | E211: VELEZ HUERTAS, RICARDO FABRICIO | F211: VELEZ | G211: HUERTAS | H211: RICARDO FABRICIO | I211: rvelezh@unprg.edu.pe | J211: @UNPRG.EDU.PE | K211: 983846148 | L211: MAESTRIA | M211: Ciencias Sociales con mención en Gestión Pública y Gerencia Social | N211: 77.3 | O211: ALCANZÓ VACANTE
A212: 211 | B212: AL | C212: 70840720 | D212: CALMET VILLEGAS CARLOS GUILLERMO | E212: CALMET VILLEGAS, CARLOS GUILLERMO | F212: CALMET | G212: VILLEGAS | H212: CARLOS GUILLERMO | I212: carloscalmet25@gmail.com | J212: @UNPRG.EDU.PE | K212: 992278663 | L212: MAESTRIA | M212: Ciencias Sociales con mención en Gestión Pública y Gerencia Social | N212: 75.6 | O212: ALCANZÓ VACANTE
A213: 212 | B213: AL | C213: 42062400 | D213: PACHERRES ALCANTARA INGRID OLGA | E213: PACHERRES ALCANTARA, INGRID OLGA | F213: PACHERRES | G213: ALCANTARA | H213: INGRID OLGA | I213: ipacherresalcantara@gmail.com | J213: @UNPRG.EDU.PE | K213: 996617036 | L213: MAESTRIA | M213: Ciencias Sociales con mención en Gestión Pública y Gerencia Social | N213: 74 | O213: ALCANZÓ VACANTE
A214: 213 | B214: AL | C214: 45038251 | D214: CUMPA PUICAN JUAN KAROLL | E214: CUMPA PUICAN, JUAN KAROLL | F214: CUMPA | G214: PUICAN | H214: JUAN KAROLL | I214: cumpap.juan@gmail.com | J214: @UNPRG.EDU.PE | K214: 939080978 | L214: MAESTRIA | M214: Ciencias Sociales con mención en Gestión Pública y Gerencia Social | N214: 73.5 | O214: ALCANZÓ VACANTE
A215: 214 | B215: AL | C215: 43734675 | D215: BUSTAMANTE AQUINO JOSÉ ANTONIO | E215: BUSTAMANTE AQUINO, JOSÉ ANTONIO | F215: BUSTAMANTE | G215: AQUINO | H215: JOSÉ ANTONIO | I215: joseantonito2646@gmail.com | J215: @UNPRG.EDU.PE | K215: 950796249 | L215: MAESTRIA | M215: Ciencias Sociales con mención en Gestión Pública y Gerencia Social | N215: 70.2 | O215: ALCANZÓ VACANTE
A216: 215 | B216: AL | C216: 71415312 | D216: ALTAMIRANO CUSMA EDSON DANIEL | E216: ALTAMIRANO CUSMA, EDSON DANIEL | F216: ALTAMIRANO | G216: CUSMA | H216: EDSON DANIEL | I216: edsondaniel2003@gmail.com | J216: @UNPRG.EDU.PE | K216: 979541769 | L216: MAESTRIA | M216: Ciencias Sociales con mención en Gestión Pública y Gerencia Social | N216: 68.6 | O216: ALCANZÓ VACANTE
A217: 216 | B217: AL | C217: 45907492 | D217: DAVILA BELLODAS KATYA FIORELLA | E217: DAVILA BELLODAS, KATYA FIORELLA | F217: DAVILA | G217: BELLODAS | H217: KATYA FIORELLA | I217: katya_davila@hotmail.com | J217: @UNPRG.EDU.PE | K217: 979014146 | L217: MAESTRIA | M217: Ciencias Sociales con mención en Gestión Pública y Gerencia Social | N217: 68.5 | O217: ALCANZÓ VACANTE
...

Sheet datos_cargar
A1: IdPer | B1: Tipo | C1: Apenom | D1: RUC | E1: Email | F1: Telefono | G1: Celular | H1: Direccion | I1: FechaNac | J1: Grado | K1: UniGrado | L1: Cargo | M1: CodigoSP | N1: Sueldo | O1: CodigoAlu | P1: Clave | Q1: EstadoDoc | R1: FIngreso | S1: Promocion | T1: sexo_alu | U1: Condicion | V1: Libro | W1: fechagrad_alu | X1: grupo_alu | Y1: fegreso_alu | Z1: fadmision_alu | AA1: fechapostulante_ps | AB1: csexpediente_ps | AC1: Folio | AD1: region_alu | AE1: trabajade_alu | AF1: trabajaen_alu | AG1: observacionACA_alu | AH1: modalidad_alu | AI1: Nombres | AJ1: ApellidoPat | AK1: ApellidoMat | AL1: DNI | AM1: gradoacademico_alu | AN1: gradoacademicouni_alu | AO1: tituloprofesional_alu | AP1: tituloprofesionaluni_alu | AQ1: EstadoPago | AR1: EAcademico_alu | AS1: EgresadoUNPRG | AT1: Profesion | AU1: GradoAcademicoCodigoUni | AV1: DistritoResidencia | AW1: ProvinciaResidencia | AX1: DepartamentoResidencia | AY1: TipoUni | AZ1: FEgreso | BA1: observacionRECA_alu | BB1: FechaReg | BC1: NroExpedienteGrado | BD1: FechaGrado | BE1: ResolucionGrado | BF1: EmailUNPRG | BG1: PuntajeExaIngreso
A2: 1 | B2: AL | C2: LLAMO DIAZ, NELSON JOSUE | D2: 75363208 | E2: nejlld25@gmail.com | F2: - | G2: 955850651 | H2: =VLOOKUP(D2,DATA_SISTEMA!$A$1:$Q$506,13,FALSE) -> ANEXO CRUCE LAS CANTERAS S/N | I2: =VLOOKUP(D2,DATA_SISTEMA!$A$1:$Q$506,7,FALSE) -> 1999-02-25 | J2: - | K2: - | L2: - | M2: 74 | N2: 0 | O2: =_xlfn.CONCAT(A2,"0020261X") -> 10020261X | P2: - | Q2: - | R2: 2026-I | S2: V | T2: =VLOOKUP(D2,DATA_SISTEMA!$A$1:$Q$506,9,FALSE) -> M | U2: A | V2: - | W2: 0000-00-00 | X2: U | Y2: - | Z2: - | AA2: 0000-00-00 | AB2: - | AC2: - | AD2: - | AE2: - | AF2: - | AG2: - | AH2: OR | AI2: NELSON JOSUE | AJ2: LLAMO | AK2: DIAZ | AL2: 75363208 | AM2: - | AN2: - | AO2: - | AP2: - | AQ2: - | AR2: - | AS2: - | AT2: - | AU2: - | AV2: =VLOOKUP(D2,DATA_SISTEMA!$A$1:$Q$506,12,FALSE) -> PATAPO | AW2: =VLOOKUP(D2,DATA_SISTEMA!$A$1:$Q$506,11,FALSE) -> CHICLAYO | AX2: =VLOOKUP(D2,DATA_SISTEMA!$A$1:$Q$506,10,FALSE) -> LAMBAYEQUE | AY2: - | AZ2: 0000-00-00 | BA2: - | BB2: 0000-00-00 | BC2: - | BD2: 0000-00-00 | BE2: - | BF2: @UNPRG.EDU.PE | BG2: 80.5
A3: 2 | B3: AL | C3: SILVA DELGADO, GHIERALD ELOY | D3: 44666269 | E3: silvaagricola0406@gmail.com | F3: - | G3: 926186587 | H3: =VLOOKUP(D3,DATA_SISTEMA!$A$1:$Q$506,13,FALSE) -> MZ -B LOTE 11 | I3: =VLOOKUP(D3,DATA_SISTEMA!$A$1:$Q$506,7,FALSE) -> 1986-12-06 | J3: - | K3: - | L3: - | M3: 74 | N3: 0 | O3: =_xlfn.CONCAT(A3,"0020261X") -> 20020261X | P3: - | Q3: - | R3: 2026-I | S3: V | T3: =VLOOKUP(D3,DATA_SISTEMA!$A$1:$Q$506,9,FALSE) -> M | U3: A | V3: - | W3: 0000-00-00 | X3: U | Y3: - | Z3: - | AA3: 0000-00-00 | AB3: - | AC3: - | AD3: - | AE3: - | AF3: - | AG3: - | AH3: OR | AI3: GHIERALD ELOY | AJ3: SILVA | AK3: DELGADO | AL3: 44666269 | AM3: - | AN3: - | AO3: - | AP3: - | AQ3: - | AR3: - | AS3: - | AT3: - | AU3: - | AV3: =VLOOKUP(D3,DATA_SISTEMA!$A$1:$Q$506,12,FALSE) -> CASTILLA | AW3: =VLOOKUP(D3,DATA_SISTEMA!$A$1:$Q$506,11,FALSE) -> PIURA | AX3: =VLOOKUP(D3,DATA_SISTEMA!$A$1:$Q$506,10,FALSE) -> PIURA | AY3: - | AZ3: 0000-00-00 | BA3: - | BB3: 0000-00-00 | BC3: - | BD3: 0000-00-00 | BE3: - | BF3: @UNPRG.EDU.PE | BG3: 74.5
A4: 3 | B4: AL | C4: CIEZA HERRERA, IVAN MARCELO | D4: 71491689 | E4: ivanciencias13@gmail.com | F4: - | G4: 968750910 | H4: =VLOOKUP(D4,DATA_SISTEMA!$A$1:$Q$506,13,FALSE) -> BLOCK 18 MZ. LT. 6B | I4: =VLOOKUP(D4,DATA_SISTEMA!$A$1:$Q$506,7,FALSE) -> 1999-08-13 | J4: - | K4: - | L4: - | M4: 74 | N4: 0 | O4: =_xlfn.CONCAT(A4,"0020261X") -> 30020261X | P4: - | Q4: - | R4: 2026-I | S4: V | T4: =VLOOKUP(D4,DATA_SISTEMA!$A$1:$Q$506,9,FALSE) -> M | U4: A | V4: - | W4: 0000-00-00 | X4: U | Y4: - | Z4: - | AA4: 0000-00-00 | AB4: - | AC4: - | AD4: - | AE4: - | AF4: - | AG4: - | AH4: OR | AI4: IVAN MARCELO | AJ4: CIEZA | AK4: HERRERA | AL4: 71491689 | AM4: - | AN4: - | AO4: - | AP4: - | AQ4: - | AR4: - | AS4: - | AT4: - | AU4: - | AV4: =VLOOKUP(D4,DATA_SISTEMA!$A$1:$Q$506,12,FALSE) -> TUMAN | AW4: =VLOOKUP(D4,DATA_SISTEMA!$A$1:$Q$506,11,FALSE) -> CHICLAYO | AX4: =VLOOKUP(D4,DATA_SISTEMA!$A$1:$Q$506,10,FALSE) -> LAMBAYEQUE | AY4: - | AZ4: 0000-00-00 | BA4: - | BB4: 0000-00-00 | BC4: - | BD4: 0000-00-00 | BE4: - | BF4: @UNPRG.EDU.PE | BG4: 74
A5: 4 | B5: AL | C5: SAUCEDO LINARES, CRISTIAN YOMAR | D5: 73462669 | E5: cristiansaucedolinares10@gmail.com | F5: - | G5: 975609988 | H5: =VLOOKUP(D5,DATA_SISTEMA!$A$1:$Q$506,13,FALSE) -> JR. JOSÉ SALINAS N° 269 - CHOTA | I5: =VLOOKUP(D5,DATA_SISTEMA!$A$1:$Q$506,7,FALSE) -> 1999-02-10 | J5: - | K5: - | L5: - | M5: 74 | N5: 0 | O5: =_xlfn.CONCAT(A5,"0020261X") -> 40020261X | P5: - | Q5: - | R5: 2026-I | S5: V | T5: =VLOOKUP(D5,DATA_SISTEMA!$A$1:$Q$506,9,FALSE) -> M | U5: A | V5: - | W5: 0000-00-00 | X5: U | Y5: - | Z5: - | AA5: 0000-00-00 | AB5: - | AC5: - | AD5: - | AE5: - | AF5: - | AG5: - | AH5: OR | AI5: CRISTIAN YOMAR | AJ5: SAUCEDO | AK5: LINARES | AL5: 73462669 | AM5: - | AN5: - | AO5: - | AP5: - | AQ5: - | AR5: - | AS5: - | AT5: - | AU5: - | AV5: =VLOOKUP(D5,DATA_SISTEMA!$A$1:$Q$506,12,FALSE) -> CHOTA | AW5: =VLOOKUP(D5,DATA_SISTEMA!$A$1:$Q$506,11,FALSE) -> CHOTA | AX5: =VLOOKUP(D5,DATA_SISTEMA!$A$1:$Q$506,10,FALSE) -> CAJAMARCA | AY5: - | AZ5: 0000-00-00 | BA5: - | BB5: 0000-00-00 | BC5: - | BD5: 0000-00-00 | BE5: - | BF5: @UNPRG.EDU.PE | BG5: 74
A6: 5 | B6: AL | C6: ARBOLEDA IMAN, JUAN MANUEL | D6: 71396806 | E6: juanarboledai1996@gmail.com | F6: - | G6: 972026173 | H6: =VLOOKUP(D6,DATA_SISTEMA!$A$1:$Q$506,13,FALSE) -> ARENALES 638 DIEGO FERRE | I6: =VLOOKUP(D6,DATA_SISTEMA!$A$1:$Q$506,7,FALSE) -> 1996-01-03 | J6: - | K6: - | L6: - | M6: 74 | N6: 0 | O6: =_xlfn.CONCAT(A6,"0020261X") -> 50020261X | P6: - | Q6: - | R6: 2026-I | S6: V | T6: =VLOOKUP(D6,DATA_SISTEMA!$A$1:$Q$506,9,FALSE) -> M | U6: A | V6: - | W6: 0000-00-00 | X6: U | Y6: - | Z6: - | AA6: 0000-00-00 | AB6: - | AC6: - | AD6: - | AE6: - | AF6: - | AG6: - | AH6: OR | AI6: JUAN MANUEL | AJ6: ARBOLEDA | AK6: IMAN | AL6: 71396806 | AM6: - | AN6: - | AO6: - | AP6: - | AQ6: - | AR6: - | AS6: - | AT6: - | AU6: - | AV6: =VLOOKUP(D6,DATA_SISTEMA!$A$1:$Q$506,12,FALSE) -> CHICLAYO | AW6: =VLOOKUP(D6,DATA_SISTEMA!$A$1:$Q$506,11,FALSE) -> CHICLAYO | AX6: =VLOOKUP(D6,DATA_SISTEMA!$A$1:$Q$506,10,FALSE) -> LAMBAYEQUE | AY6: - | AZ6: 0000-00-00 | BA6: - | BB6: 0000-00-00 | BC6: - | BD6: 0000-00-00 | BE6: - | BF6: @UNPRG.EDU.PE | BG6: 73.5
A7: 6 | B7: AL | C7: AREVALO CORONEL, RAUL JOEL | D7: 43111414 | E7: rauljac86@outlook.com | F7: - | G7: 939737207 | H7: =VLOOKUP(D7,DATA_SISTEMA!$A$1:$Q$506,13,FALSE) -> CA. WIRACOCHA N° 667-2DO PISO | I7: =VLOOKUP(D7,DATA_SISTEMA!$A$1:$Q$506,7,FALSE) -> 1985-06-05 | J7: - | K7: - | L7: - | M7: 74 | N7: 0 | O7: =_xlfn.CONCAT(A7,"0020261X") -> 60020261X | P7: - | Q7: - | R7: 2026-I | S7: V | T7: =VLOOKUP(D7,DATA_SISTEMA!$A$1:$Q$506,9,FALSE) -> M | U7: A | V7: - | W7: 0000-00-00 | X7: U | Y7: - | Z7: - | AA7: 0000-00-00 | AB7: - | AC7: - | AD7: - | AE7: - | AF7: - | AG7: - | AH7: OR | AI7: RAUL JOEL | AJ7: AREVALO | AK7: CORONEL | AL7: 43111414 | AM7: - | AN7: - | AO7: - | AP7: - | AQ7: - | AR7: - | AS7: - | AT7: - | AU7: - | AV7: =VLOOKUP(D7,DATA_SISTEMA!$A$1:$Q$506,12,FALSE) -> LA VICTORIA | AW7: =VLOOKUP(D7,DATA_SISTEMA!$A$1:$Q$506,11,FALSE) -> CHICLAYO | AX7: =VLOOKUP(D7,DATA_SISTEMA!$A$1:$Q$506,10,FALSE) -> LAMBAYEQUE | AY7: - | AZ7: 0000-00-00 | BA7: - | BB7: 0000-00-00 | BC7: - | BD7: 0000-00-00 | BE7: - | BF7: @UNPRG.EDU.PE | BG7: 72.5
A8: 7 | B8: AL | C8: GUEVARA PORTILLO, FRANCO DAVID | D8: 60258953 | E8: francod.gp@gmail.com | F8: - | G8: 990453660 | H8: =VLOOKUP(D8,DATA_SISTEMA!$A$1:$Q$506,13,FALSE) -> CALLE LOS PETALOS 299 - URB. CARLOS STEIN | I8: =VLOOKUP(D8,DATA_SISTEMA!$A$1:$Q$506,7,FALSE) -> 1995-07-13 | J8: - | K8: - | L8: - | M8: 74 | N8: 0 | O8: =_xlfn.CONCAT(A8,"0020261X") -> 70020261X | P8: - | Q8: - | R8: 2026-I | S8: V | T8: =VLOOKUP(D8,DATA_SISTEMA!$A$1:$Q$506,9,FALSE) -> M | U8: A | V8: - | W8: 0000-00-00 | X8: U | Y8: - | Z8: - | AA8: 0000-00-00 | AB8: - | AC8: - | AD8: - | AE8: - | AF8: - | AG8: - | AH8: OR | AI8: FRANCO DAVID | AJ8: GUEVARA | AK8: PORTILLO | AL8: 60258953 | AM8: - | AN8: - | AO8: - | AP8: - | AQ8: - | AR8: - | AS8: - | AT8: - | AU8: - | AV8: =VLOOKUP(D8,DATA_SISTEMA!$A$1:$Q$506,12,FALSE) -> JOSE LEONARDO ORTIZ | AW8: =VLOOKUP(D8,DATA_SISTEMA!$A$1:$Q$506,11,FALSE) -> CHICLAYO | AX8: =VLOOKUP(D8,DATA_SISTEMA!$A$1:$Q$506,10,FALSE) -> LAMBAYEQUE | AY8: - | AZ8: 0000-00-00 | BA8: - | BB8: 0000-00-00 | BC8: - | BD8: 0000-00-00 | BE8: - | BF8: @UNPRG.EDU.PE | BG8: 72.5
A9: 8 | B9: AL | C9: OJEDA CAPUÑAY, RENZO PAOLO | D9: 73025102 | E9: renzo_ojeda_0304@outlook.com | F9: - | G9: 963584802 | H9: =VLOOKUP(D9,DATA_SISTEMA!$A$1:$Q$506,13,FALSE) -> TUPAC AMARU #300 - P.J. SANTA ROSA | I9: =VLOOKUP(D9,DATA_SISTEMA!$A$1:$Q$506,7,FALSE) -> 1998-04-03 | J9: - | K9: - | L9: - | M9: 74 | N9: 0 | O9: =_xlfn.CONCAT(A9,"0020261X") -> 80020261X | P9: - | Q9: - | R9: 2026-I | S9: V | T9: =VLOOKUP(D9,DATA_SISTEMA!$A$1:$Q$506,9,FALSE) -> M | U9: A | V9: - | W9: 0000-00-00 | X9: U | Y9: - | Z9: - | AA9: 0000-00-00 | AB9: - | AC9: - | AD9: - | AE9: - | AF9: - | AG9: - | AH9: OR | AI9: RENZO PAOLO | AJ9: OJEDA | AK9: CAPUÑAY | AL9: 73025102 | AM9: - | AN9: - | AO9: - | AP9: - | AQ9: - | AR9: - | AS9: - | AT9: - | AU9: - | AV9: =VLOOKUP(D9,DATA_SISTEMA!$A$1:$Q$506,12,FALSE) -> LAMBAYEQUE | AW9: =VLOOKUP(D9,DATA_SISTEMA!$A$1:$Q$506,11,FALSE) -> LAMBAYEQUE | AX9: =VLOOKUP(D9,DATA_SISTEMA!$A$1:$Q$506,10,FALSE) -> LAMBAYEQUE | AY9: - | AZ9: 0000-00-00 | BA9: - | BB9: 0000-00-00 | BC9: - | BD9: 0000-00-00 | BE9: - | BF9: @UNPRG.EDU.PE | BG9: 72.5
A10: 9 | B10: AL | C10: HUAYTALLA YARANGA, JOSE LUIS | D10: 75720372 | E10: jose.huaytalla21@gmail.com | F10: - | G10: 941361826 | H10: =VLOOKUP(D10,DATA_SISTEMA!$A$1:$Q$506,13,FALSE) -> JR ALHUCEMAS 1718 COOP LAS FLORES DE PRIMAVERA | I10: =VLOOKUP(D10,DATA_SISTEMA!$A$1:$Q$506,7,FALSE) -> 1996-11-14 | J10: - | K10: - | L10: - | M10: 74 | N10: 0 | O10: =_xlfn.CONCAT(A10,"0020261X") -> 90020261X | P10: - | Q10: - | R10: 2026-I | S10: V | T10: =VLOOKUP(D10,DATA_SISTEMA!$A$1:$Q$506,9,FALSE) -> M | U10: A | V10: - | W10: 0000-00-00 | X10: U | Y10: - | Z10: - | AA10: 0000-00-00 | AB10: - | AC10: - | AD10: - | AE10: - | AF10: - | AG10: - | AH10: OR | AI10: JOSE LUIS | AJ10: HUAYTALLA | AK10: YARANGA | AL10: 75720372 | AM10: - | AN10: - | AO10: - | AP10: - | AQ10: - | AR10: - | AS10: - | AT10: - | AU10: - | AV10: =VLOOKUP(D10,DATA_SISTEMA!$A$1:$Q$506,12,FALSE) -> SAN JUAN DE LURIGANCHO | AW10: =VLOOKUP(D10,DATA_SISTEMA!$A$1:$Q$506,11,FALSE) -> LIMA | AX10: =VLOOKUP(D10,DATA_SISTEMA!$A$1:$Q$506,10,FALSE) -> LIMA | AY10: - | AZ10: 0000-00-00 | BA10: - | BB10: 0000-00-00 | BC10: - | BD10: 0000-00-00 | BE10: - | BF10: @UNPRG.EDU.PE | BG10: 72
A11: 10 | B11: AL | C11: SAAVEDRA RUIZ, AQUILES | D11: 46135037 | E11: aquiles_sr4@hotmail.com | F11: - | G11: 918313510 | H11: =VLOOKUP(D11,DATA_SISTEMA!$A$1:$Q$506,13,FALSE) -> CENTRO POBLADO EL CHORRO - S/N POMALCA | I11: =VLOOKUP(D11,DATA_SISTEMA!$A$1:$Q$506,7,FALSE) -> 1989-12-15 | J11: - | K11: - | L11: - | M11: 74 | N11: 0 | O11: =_xlfn.CONCAT(A11,"0020261X") -> 100020261X | P11: - | Q11: - | R11: 2026-I | S11: V | T11: =VLOOKUP(D11,DATA_SISTEMA!$A$1:$Q$506,9,FALSE) -> M | U11: A | V11: - | W11: 0000-00-00 | X11: U | Y11: - | Z11: - | AA11: 0000-00-00 | AB11: - | AC11: - | AD11: - | AE11: - | AF11: - | AG11: - | AH11: OR | AI11: AQUILES | AJ11: SAAVEDRA | AK11: RUIZ | AL11: 46135037 | AM11: - | AN11: - | AO11: - | AP11: - | AQ11: - | AR11: - | AS11: - | AT11: - | AU11: - | AV11: =VLOOKUP(D11,DATA_SISTEMA!$A$1:$Q$506,12,FALSE) -> POMALCA | AW11: =VLOOKUP(D11,DATA_SISTEMA!$A$1:$Q$506,11,FALSE) -> CHICLAYO | AX11: =VLOOKUP(D11,DATA_SISTEMA!$A$1:$Q$506,10,FALSE) -> LAMBAYEQUE | AY11: - | AZ11: 0000-00-00 | BA11: - | BB11: 0000-00-00 | BC11: - | BD11: 0000-00-00 | BE11: - | BF11: @UNPRG.EDU.PE | BG11: 70
A12: 11 | B12: AL | C12: MANAYAY MANAYAY, JOSELITO | D12: 48199611 | E12: jmanayaym@hotmail.com | F12: - | G12: 925882492 | H12: =VLOOKUP(D12,DATA_SISTEMA!$A$1:$Q$506,13,FALSE) -> PROLONGACION BRITALDO GONZALES MZ H LT 4 | I12: =VLOOKUP(D12,DATA_SISTEMA!$A$1:$Q$506,7,FALSE) -> 1992-01-03 | J12: - | K12: - | L12: - | M12: 74 | N12: 0 | O12: =_xlfn.CONCAT(A12,"0020261X") -> 110020261X | P12: - | Q12: - | R12: 2026-I | S12: V | T12: =VLOOKUP(D12,DATA_SISTEMA!$A$1:$Q$506,9,FALSE) -> M | U12: A | V12: - | W12: 0000-00-00 | X12: U | Y12: - | Z12: - | AA12: 0000-00-00 | AB12: - | AC12: - | AD12: - | AE12: - | AF12: - | AG12: - | AH12: OR | AI12: JOSELITO | AJ12: MANAYAY | AK12: MANAYAY | AL12: 48199611 | AM12: - | AN12: - | AO12: - | AP12: - | AQ12: - | AR12: - | AS12: - | AT12: - | AU12: - | AV12: =VLOOKUP(D12,DATA_SISTEMA!$A$1:$Q$506,12,FALSE) -> PUEBLO NUEVO | AW12: =VLOOKUP(D12,DATA_SISTEMA!$A$1:$Q$506,11,FALSE) -> FERREÑAFE | AX12: =VLOOKUP(D12,DATA_SISTEMA!$A$1:$Q$506,10,FALSE) -> LAMBAYEQUE | AY12: - | AZ12: 0000-00-00 | BA12: - | BB12: 0000-00-00 | BC12: - | BD12: 0000-00-00 | BE12: - | BF12: @UNPRG.EDU.PE | BG12: 68.5
A13: 12 | B13: AL | C13: DE LA CRUZ DE LA CRUZ, LUIS ARMANDO | D13: 73514125 | E13: luisdelacruz1409@gmail.com | F13: - | G13: 973854830 | H13: =VLOOKUP(D13,DATA_SISTEMA!$A$1:$Q$506,13,FALSE) -> PUEBLO JOVEN SAN JUAN MZ D LT N°3-CHICLAYO | I13: =VLOOKUP(D13,DATA_SISTEMA!$A$1:$Q$506,7,FALSE) -> 1997-09-14 | J13: - | K13: - | L13: - | M13: 74 | N13: 0 | O13: =_xlfn.CONCAT(A13,"0020261X") -> 120020261X | P13: - | Q13: - | R13: 2026-I | S13: V | T13: =VLOOKUP(D13,DATA_SISTEMA!$A$1:$Q$506,9,FALSE) -> M | U13: A | V13: - | W13: 0000-00-00 | X13: U | Y13: - | Z13: - | AA13: 0000-00-00 | AB13: - | AC13: - | AD13: - | AE13: - | AF13: - | AG13: - | AH13: OR | AI13: LUIS ARMANDO | AJ13: DE LA CRUZ | AK13: DE LA CRUZ | AL13: 73514125 | AM13: - | AN13: - | AO13: - | AP13: - | AQ13: - | AR13: - | AS13: - | AT13: - | AU13: - | AV13: =VLOOKUP(D13,DATA_SISTEMA!$A$1:$Q$506,12,FALSE) -> CAÑARIS | AW13: =VLOOKUP(D13,DATA_SISTEMA!$A$1:$Q$506,11,FALSE) -> FERREÑAFE | AX13: =VLOOKUP(D13,DATA_SISTEMA!$A$1:$Q$506,10,FALSE) -> LAMBAYEQUE | AY13: - | AZ13: 0000-00-00 | BA13: - | BB13: 0000-00-00 | BC13: - | BD13: 0000-00-00 | BE13: - | BF13: @UNPRG.EDU.PE | BG13: 67.5
... A31: 30 | B31: AL | C31: GUERREROS SALAZAR, ANGIE LESLIE | D31: 73699282 | E31: arq.angielgs@gmail.com | F31: - | G31: 942238971 | H31: =VLOOKUP(D31,DATA_SISTEMA!$A$1:$Q$506,13,FALSE) -> INDEPENDENCIA 725 | I31: =VLOOKUP(D31,DATA_SISTEMA!$A$1:$Q$506,7,FALSE) -> 1996-03-09 | J31: - | K31: - | L31: - | M31: 269 | N31: 0 | O31: =_xlfn.CONCAT(A31,"0020261X") -> 300020261X | P31: - | Q31: - | R31: 2026-I | S31: IV | T31: =VLOOKUP(D31,DATA_SISTEMA!$A$1:$Q$506,9,FALSE) -> F | U31: A | V31: - | W31: 0000-00-00 | X31: U | Y31: - | Z31: - | AA31: 0000-00-00 | AB31: - | AC31: - | AD31: - | AE31: - | AF31: - | AG31: - | AH31: OR | AI31: ANGIE LESLIE | AJ31: GUERREROS | AK31: SALAZAR | AL31: 73699282 | AM31: - | AN31: - | AO31: - | AP31: - | AQ31: - | AR31: - | AS31: - | AT31: - | AU31: - | AV31: =VLOOKUP(D31,DATA_SISTEMA!$A$1:$Q$506,12,FALSE) -> CHICLAYO | AW31: =VLOOKUP(D31,DATA_SISTEMA!$A$1:$Q$506,11,FALSE) -> CHICLAYO | AX31: =VLOOKUP(D31,DATA_SISTEMA!$A$1:$Q$506,10,FALSE) -> LAMBAYEQUE | AY31: - | AZ31: 0000-00-00 | BA31: - | BB31: 0000-00-00 | BC31: - | BD31: 0000-00-00 | BE31: - | BF31: @UNPRG.EDU.PE | BG31: 64.7
A32: 31 | B32: AL | C32: LACERNA ZUTA, KATHY | D32: 71208115 | E32: Kathy.lacerna.zuta@gmail.com | F32: - | G32: 970963109 | H32: =VLOOKUP(D32,DATA_SISTEMA!$A$1:$Q$506,13,FALSE) -> LA MERCED 429 | I32: =VLOOKUP(D32,DATA_SISTEMA!$A$1:$Q$506,7,FALSE) -> 1995-11-15 | J32: - | K32: - | L32: - | M32: 269 | N32: 0 | O32: =_xlfn.CONCAT(A32,"0020261X") -> 310020261X | P32: - | Q32: - | R32: 2026-I | S32: IV | T32: =VLOOKUP(D32,DATA_SISTEMA!$A$1:$Q$506,9,FALSE) -> F | U32: A | V32: - | W32: 0000-00-00 | X32: U | Y32: - | Z32: - | AA32: 0000-00-00 | AB32: - | AC32: - | AD32: - | AE32: - | AF32: - | AG32: - | AH32: OR | AI32: KATHY | AJ32: LACERNA | AK32: ZUTA | AL32: 71208115 | AM32: - | AN32: - | AO32: - | AP32: - | AQ32: - | AR32: - | AS32: - | AT32: - | AU32: - | AV32: =VLOOKUP(D32,DATA_SISTEMA!$A$1:$Q$506,12,FALSE) -> CHACHAPOYAS | AW32: =VLOOKUP(D32,DATA_SISTEMA!$A$1:$Q$506,11,FALSE) -> CHACHAPOYAS | AX32: =VLOOKUP(D32,DATA_SISTEMA!$A$1:$Q$506,10,FALSE) -> AMAZONAS | AY32: - | AZ32: 0000-00-00 | BA32: - | BB32: 0000-00-00 | BC32: - | BD32: 0000-00-00 | BE32: - | BF32: @UNPRG.EDU.PE | BG32: 63.5
A33: 32 | B33: AL | C33: ROJAS MORENO, ANDERSON DALFRED | D33: 45586127 | E33: dalfred_g@hotmail.com | F33: - | G33: 954639109 | H33: =VLOOKUP(D33,DATA_SISTEMA!$A$1:$Q$506,13,FALSE) -> CALLE LAMBAYEQUE #860 P.J SANTA ROSA | I33: =VLOOKUP(D33,DATA_SISTEMA!$A$1:$Q$506,7,FALSE) -> 1988-12-26 | J33: - | K33: - | L33: - | M33: 269 | N33: 0 | O33: =_xlfn.CONCAT(A33,"0020261X") -> 320020261X | P33: - | Q33: - | R33: 2026-I | S33: IV | T33: =VLOOKUP(D33,DATA_SISTEMA!$A$1:$Q$506,9,FALSE) -> M | U33: A | V33: - | W33: 0000-00-00 | X33: U | Y33: - | Z33: - | AA33: 0000-00-00 | AB33: - | AC33: - | AD33: - | AE33: - | AF33: - | AG33: - | AH33: OR | AI33: ANDERSON DALFRED | AJ33: ROJAS | AK33: MORENO | AL33: 45586127 | AM33: - | AN33: - | AO33: - | AP33: - | AQ33: - | AR33: - | AS33: - | AT33: - | AU33: - | AV33: =VLOOKUP(D33,DATA_SISTEMA!$A$1:$Q$506,12,FALSE) -> LAMBAYEQUE | AW33: =VLOOKUP(D33,DATA_SISTEMA!$A$1:$Q$506,11,FALSE) -> LAMBAYEQUE | AX33: =VLOOKUP(D33,DATA_SISTEMA!$A$1:$Q$506,10,FALSE) -> LAMBAYEQUE | AY33: - | AZ33: 0000-00-00 | BA33: - | BB33: 0000-00-00 | BC33: - | BD33: 0000-00-00 | BE33: - | BF33: @UNPRG.EDU.PE | BG33: 63.1
A34: 33 | B34: AL | C34: EFFIO BUSTAMANTE, JOEL ALBERTO | D34: 72729965 | E34: northsiderecords.26@gmail.com | F34: - | G34: 900794195 | H34: =VLOOKUP(D34,DATA_SISTEMA!$A$1:$Q$506,13,FALSE) -> CA. ANDRES AVELINO CACEREZ 859. URB. DIEGO FERRE | I34: =VLOOKUP(D34,DATA_SISTEMA!$A$1:$Q$506,7,FALSE) -> 1994-04-16 | J34: - | K34: - | L34: - | M34: 269 | N34: 0 | O34: =_xlfn.CONCAT(A34,"0020261X") -> 330020261X | P34: - | Q34: - | R34: 2026-I | S34: IV | T34: =VLOOKUP(D34,DATA_SISTEMA!$A$1:$Q$506,9,FALSE) -> M | U34: A | V34: - | W34: 0000-00-00 | X34: U | Y34: - | Z34: - | AA34: 0000-00-00 | AB34: - | AC34: - | AD34: - | AE34: - | AF34: - | AG34: - | AH34: OR | AI34: JOEL ALBERTO | AJ34: EFFIO | AK34: BUSTAMANTE | AL34: 72729965 | AM34: - | AN34: - | AO34: - | AP34: - | AQ34: - | AR34: - | AS34: - | AT34: - | AU34: - | AV34: =VLOOKUP(D34,DATA_SISTEMA!$A$1:$Q$506,12,FALSE) -> CHICLAYO | AW34: =VLOOKUP(D34,DATA_SISTEMA!$A$1:$Q$506,11,FALSE) -> CHICLAYO | AX34: =VLOOKUP(D34,DATA_SISTEMA!$A$1:$Q$506,10,FALSE) -> LAMBAYEQUE | AY34: - | AZ34: 0000-00-00 | BA34: - | BB34: 0000-00-00 | BC34: - | BD34: 0000-00-00 | BE34: - | BF34: @UNPRG.EDU.PE | BG34: 61.9
A35: 34 | B35: AL | C35: VALDERA CHAFLOQUE, MANUEL OSWALDO | D35: 77036935 | E35: arq.valdera@gmail.com | F35: - | G35: 975822946 | H35: =VLOOKUP(D35,DATA_SISTEMA!$A$1:$Q$506,13,FALSE) -> SOL DE LA ALAMEDA REAL IV DE LAMBAYEQUE | I35: =VLOOKUP(D35,DATA_SISTEMA!$A$1:$Q$506,7,FALSE) -> 1994-09-24 | J35: - | K35: - | L35: - | M35: 269 | N35: 0 | O35: =_xlfn.CONCAT(A35,"0020261X") -> 340020261X | P35: - | Q35: - | R35: 2026-I | S35: IV | T35: =VLOOKUP(D35,DATA_SISTEMA!$A$1:$Q$506,9,FALSE) -> M | U35: A | V35: - | W35: 0000-00-00 | X35: U | Y35: - | Z35: - | AA35: 0000-00-00 | AB35: - | AC35: - | AD35: - | AE35: - | AF35: - | AG35: - | AH35: OR | AI35: MANUEL OSWALDO | AJ35: VALDERA | AK35: CHAFLOQUE | AL35: 77036935 | AM35: - | AN35: - | AO35: - | AP35: - | AQ35: - | AR35: - | AS35: - | AT35: - | AU35: - | AV35: =VLOOKUP(D35,DATA_SISTEMA!$A$1:$Q$506,12,FALSE) -> LAMBAYEQUE | AW35: =VLOOKUP(D35,DATA_SISTEMA!$A$1:$Q$506,11,FALSE) -> LAMBAYEQUE | AX35: =VLOOKUP(D35,DATA_SISTEMA!$A$1:$Q$506,10,FALSE) -> LAMBAYEQUE | AY35: - | AZ35: 0000-00-00 | BA35: - | BB35: 0000-00-00 | BC35: - | BD35: 0000-00-00 | BE35: - | BF35: @UNPRG.EDU.PE | BG35: 61.9
A36: 35 | B36: AL | C36: DIAZ CHICLAYO, SANDRA MELISSA | D36: 47186679 | E36: diazchiclayosm@gmail.com | F36: - | G36: 916705746 | H36: =VLOOKUP(D36,DATA_SISTEMA!$A$1:$Q$506,13,FALSE) -> LAS MAGNOLIAS 440 URB LOS PARQUES | I36: =VLOOKUP(D36,DATA_SISTEMA!$A$1:$Q$506,7,FALSE) -> 1992-04-10 | J36: - | K36: - | L36: - | M36: 269 | N36: 0 | O36: =_xlfn.CONCAT(A36,"0020261X") -> 350020261X | P36: - | Q36: - | R36: 2026-I | S36: IV | T36: =VLOOKUP(D36,DATA_SISTEMA!$A$1:$Q$506,9,FALSE) -> F | U36: A | V36: - | W36: 0000-00-00 | X36: U | Y36: - | Z36: - | AA36: 0000-00-00 | AB36: - | AC36: - | AD36: - | AE36: - | AF36: - | AG36: - | AH36: OR | AI36: SANDRA MELISSA | AJ36: DIAZ | AK36: CHICLAYO | AL36: 47186679 | AM36: - | AN36: - | AO36: - | AP36: - | AQ36: - | AR36: - | AS36: - | AT36: - | AU36: - | AV36: =VLOOKUP(D36,DATA_SISTEMA!$A$1:$Q$506,12,FALSE) -> CHICLAYO | AW36: =VLOOKUP(D36,DATA_SISTEMA!$A$1:$Q$506,11,FALSE) -> CHICLAYO | AX36: =VLOOKUP(D36,DATA_SISTEMA!$A$1:$Q$506,10,FALSE) -> LAMBAYEQUE | AY36: - | AZ36: 0000-00-00 | BA36: - | BB36: 0000-00-00 | BC36: - | BD36: 0000-00-00 | BE36: - | BF36: @UNPRG.EDU.PE | BG36: 60
A37: 36 | B37: AL | C37: CARMONA TORRES, DIEGO ALONSO | D37: 71089422 | E37: carmonad665@gmail.com | F37: - | G37: 997645512 | H37: =VLOOKUP(D37,DATA_SISTEMA!$A$1:$Q$506,13,FALSE) -> JR. CINCO ESQUINAS 1056 | I37: =VLOOKUP(D37,DATA_SISTEMA!$A$1:$Q$506,7,FALSE) -> 2004-02-22 | J37: - | K37: - | L37: - | M37: 269 | N37: 0 | O37: =_xlfn.CONCAT(A37,"0020261X") -> 360020261X | P37: - | Q37: - | R37: 2026-I | S37: IV | T37: =VLOOKUP(D37,DATA_SISTEMA!$A$1:$Q$506,9,FALSE) -> M | U37: A | V37: - | W37: 0000-00-00 | X37: U | Y37: - | Z37: - | AA37: 0000-00-00 | AB37: - | AC37: - | AD37: - | AE37: - | AF37: - | AG37: - | AH37: OR | AI37: DIEGO ALONSO | AJ37: CARMONA | AK37: TORRES | AL37: 71089422 | AM37: - | AN37: - | AO37: - | AP37: - | AQ37: - | AR37: - | AS37: - | AT37: - | AU37: - | AV37: =VLOOKUP(D37,DATA_SISTEMA!$A$1:$Q$506,12,FALSE) -> CAJAMARCA | AW37: =VLOOKUP(D37,DATA_SISTEMA!$A$1:$Q$506,11,FALSE) -> CAJAMARCA | AX37: =VLOOKUP(D37,DATA_SISTEMA!$A$1:$Q$506,10,FALSE) -> CAJAMARCA | AY37: - | AZ37: 0000-00-00 | BA37: - | BB37: 0000-00-00 | BC37: - | BD37: 0000-00-00 | BE37: - | BF37: @UNPRG.EDU.PE | BG37: 59.8
A38: 37 | B38: AL | C38: AREVALO FRIAS, JORDDI JHANDERLY | D38: 71524448 | E38: arevalofrias720@gmail.com | F38: - | G38: 932957667 | H38: =VLOOKUP(D38,DATA_SISTEMA!$A$1:$Q$506,13,FALSE) -> CALLE: JUDA MZ:L LOTE:6 URB.MIRAFLORES II - LAMBAYEQUE – CHICLAYO | I38: =VLOOKUP(D38,DATA_SISTEMA!$A$1:$Q$506,7,FALSE) -> 1994-09-20 | J38: - | K38: - | L38: - | M38: 269 | N38: 0 | O38: =_xlfn.CONCAT(A38,"0020261X") -> 370020261X | P38: - | Q38: - | R38: 2026-I | S38: IV | T38: =VLOOKUP(D38,DATA_SISTEMA!$A$1:$Q$506,9,FALSE) -> M | U38: A | V38: - | W38: 0000-00-00 | X38: U | Y38: - | Z38: - | AA38: 0000-00-00 | AB38: - | AC38: - | AD38: - | AE38: - | AF38: - | AG38: - | AH38: OR | AI38: JORDDI JHANDERLY | AJ38: AREVALO | AK38: FRIAS | AL38: 71524448 | AM38: - | AN38: - | AO38: - | AP38: - | AQ38: - | AR38: - | AS38: - | AT38: - | AU38: - | AV38: =VLOOKUP(D38,DATA_SISTEMA!$A$1:$Q$506,12,FALSE) -> CHICLAYO | AW38: =VLOOKUP(D38,DATA_SISTEMA!$A$1:$Q$506,11,FALSE) -> CHICLAYO | AX38: =VLOOKUP(D38,DATA_SISTEMA!$A$1:$Q$506,10,FALSE) -> LAMBAYEQUE | AY38: - | AZ38: 0000-00-00 | BA38: - | BB38: 0000-00-00 | BC38: - | BD38: 0000-00-00 | BE38: - | BF38: @UNPRG.EDU.PE | BG38: 57.2
A39: 38 | B39: AL | C39: REYES NÚÑEZ, BRENDA SHEILY IMABELLY | D39: 46876752 | E39: brerenu@hotmail.com | F39: - | G39: 976169053 | H39: =VLOOKUP(D39,DATA_SISTEMA!$A$1:$Q$506,13,FALSE) -> URB. DERRAMA MAGISTERIAL MZ I1 LOTE 8 | I39: =VLOOKUP(D39,DATA_SISTEMA!$A$1:$Q$506,7,FALSE) -> 1991-03-24 | J39: - | K39: - | L39: - | M39: 269 | N39: 0 | O39: =_xlfn.CONCAT(A39,"0020261X") -> 380020261X | P39: - | Q39: - | R39: 2026-I | S39: IV | T39: =VLOOKUP(D39,DATA_SISTEMA!$A$1:$Q$506,9,FALSE) -> F | U39: A | V39: - | W39: 0000-00-00 | X39: U | Y39: - | Z39: - | AA39: 0000-00-00 | AB39: - | AC39: - | AD39: - | AE39: - | AF39: - | AG39: - | AH39: OR | AI39: BRENDA SHEILY IMABELLY | AJ39: REYES | AK39: NÚÑEZ | AL39: 46876752 | AM39: - | AN39: - | AO39: - | AP39: - | AQ39: - | AR39: - | AS39: - | AT39: - | AU39: - | AV39: =VLOOKUP(D39,DATA_SISTEMA!$A$1:$Q$506,12,FALSE) -> CHICLAYO | AW39: =VLOOKUP(D39,DATA_SISTEMA!$A$1:$Q$506,11,FALSE) -> CHICLAYO | AX39: =VLOOKUP(D39,DATA_SISTEMA!$A$1:$Q$506,10,FALSE) -> LAMBAYEQUE | AY39: - | AZ39: 0000-00-00 | BA39: - | BB39: 0000-00-00 | BC39: - | BD39: 0000-00-00 | BE39: - | BF39: @UNPRG.EDU.PE | BG39: 57.2
A40: 39 | B40: AL | C40: CESPEDES RINZA, JACKELINE MARGARITA | D40: 75875291 | E40: jackelinecatorce@gmail.com | F40: - | G40: 922815639 | H40: =VLOOKUP(D40,DATA_SISTEMA!$A$1:$Q$506,13,FALSE) -> AV. LUIS ABELARDO TAKAHASHI 669 | I40: =VLOOKUP(D40,DATA_SISTEMA!$A$1:$Q$506,7,FALSE) -> 1996-11-14 | J40: - | K40: - | L40: - | M40: 269 | N40: 0 | O40: =_xlfn.CONCAT(A40,"0020261X") -> 390020261X | P40: - | Q40: - | R40: 2026-I | S40: IV | T40: =VLOOKUP(D40,DATA_SISTEMA!$A$1:$Q$506,9,FALSE) -> F | U40: A | V40: - | W40: 0000-00-00 | X40: U | Y40: - | Z40: - | AA40: 0000-00-00 | AB40: - | AC40: - | AD40: - | AE40: - | AF40: - | AG40: - | AH40: OR | AI40: JACKELINE MARGARITA | AJ40: CESPEDES | AK40: RINZA | AL40: 75875291 | AM40: - | AN40: - | AO40: - | AP40: - | AQ40: - | AR40: - | AS40: - | AT40: - | AU40: - | AV40: =VLOOKUP(D40,DATA_SISTEMA!$A$1:$Q$506,12,FALSE) -> FERREÑAFE | AW40: =VLOOKUP(D40,DATA_SISTEMA!$A$1:$Q$506,11,FALSE) -> FERREÑAFE | AX40: =VLOOKUP(D40,DATA_SISTEMA!$A$1:$Q$506,10,FALSE) -> LAMBAYEQUE | AY40: - | AZ40: 0000-00-00 | BA40: - | BB40: 0000-00-00 | BC40: - | BD40: 0000-00-00 | BE40: - | BF40: @UNPRG.EDU.PE | BG40: 57.1
A41: 40 | B41: AL | C41: HUILLCA BRIONES, DAVID ELKY GUILLERMO | D41: 47409507 | E41: ghuillca2@gmail.com | F41: - | G41: 995782624 | H41: =VLOOKUP(D41,DATA_SISTEMA!$A$1:$Q$506,13,FALSE) -> ELIAS AGUIRRE 947 | I41: =VLOOKUP(D41,DATA_SISTEMA!$A$1:$Q$506,7,FALSE) -> 1991-08-18 | J41: - | K41: - | L41: - | M41: 269 | N41: 0 | O41: =_xlfn.CONCAT(A41,"0020261X") -> 400020261X | P41: - | Q41: - | R41: 2026-I | S41: IV | T41: =VLOOKUP(D41,DATA_SISTEMA!$A$1:$Q$506,9,FALSE) -> M | U41: A | V41: - | W41: 0000-00-00 | X41: U | Y41: - | Z41: - | AA41: 0000-00-00 | AB41: - | AC41: - | AD41: - | AE41: - | AF41: - | AG41: - | AH41: OR | AI41: DAVID ELKY GUILLERMO | AJ41: HUILLCA | AK41: BRIONES | AL41: 47409507 | AM41: - | AN41: - | AO41: - | AP41: - | AQ41: - | AR41: - | AS41: - | AT41: - | AU41: - | AV41: =VLOOKUP(D41,DATA_SISTEMA!$A$1:$Q$506,12,FALSE) -> CHICLAYO | AW41: =VLOOKUP(D41,DATA_SISTEMA!$A$1:$Q$506,11,FALSE) -> CHICLAYO | AX41: =VLOOKUP(D41,DATA_SISTEMA!$A$1:$Q$506,10,FALSE) -> LAMBAYEQUE | AY41: - | AZ41: 0000-00-00 | BA41: - | BB41: 0000-00-00 | BC41: - | BD41: 0000-00-00 | BE41: - | BF41: @UNPRG.EDU.PE | BG41: 47.5
A42: 41 | B42: AL | C42: TANTALEAN RUIZ, ELMER ENRIQUE | D42: 76458509 | E42: etantaleanr@unprg.edu.pe | F42: - | G42: 996103952 | H42: =VLOOKUP(D42,DATA_SISTEMA!$A$1:$Q$506,13,FALSE) -> SIMÓN BOLIVAR MZ5 LT3 – CHICLAYO, CHICLAYO, LAMBAYEQUE | I42: =VLOOKUP(D42,DATA_SISTEMA!$A$1:$Q$506,7,FALSE) -> 2001-07-21 | J42: - | K42: - | L42: - | M42: 26 | N42: 0 | O42: =_xlfn.CONCAT(A42,"0020261X") -> 410020261X | P42: - | Q42: - | R42: 2026-I | S42: XIII | T42: =VLOOKUP(D42,DATA_SISTEMA!$A$1:$Q$506,9,FALSE) -> M | U42: A | V42: - | W42: 0000-00-00 | X42: U | Y42: - | Z42: - | AA42: 0000-00-00 | AB42: - | AC42: - | AD42: - | AE42: - | AF42: - | AG42: - | AH42: OR | AI42: ELMER ENRIQUE | AJ42: TANTALEAN | AK42: RUIZ | AL42: 76458509 | AM42: - | AN42: - | AO42: - | AP42: - | AQ42: - | AR42: - | AS42: - | AT42: - | AU42: - | AV42: =VLOOKUP(D42,DATA_SISTEMA!$A$1:$Q$506,12,FALSE) -> CHICLAYO | AW42: =VLOOKUP(D42,DATA_SISTEMA!$A$1:$Q$506,11,FALSE) -> CHICLAYO | AX42: =VLOOKUP(D42,DATA_SISTEMA!$A$1:$Q$506,10,FALSE) -> LAMBAYEQUE | AY42: - | AZ42: 0000-00-00 | BA42: - | BB42: 0000-00-00 | BC42: - | BD42: 0000-00-00 | BE42: - | BF42: @UNPRG.EDU.PE | BG42: 84.5
A43: 42 | B43: AL | C43: VELA REQUEJO, LUIS GUSTAVO | D43: 46445208 | E43: vela.ing@hotmail.com | F43: - | G43: 977956362 | H43: =VLOOKUP(D43,DATA_SISTEMA!$A$1:$Q$506,13,FALSE) -> CALLE MANTARO 250, PJ SAN NICOLAS | I43: =VLOOKUP(D43,DATA_SISTEMA!$A$1:$Q$506,7,FALSE) -> 1989-03-08 | J43: - | K43: - | L43: - | M43: 26 | N43: 0 | O43: =_xlfn.CONCAT(A43,"0020261X") -> 420020261X | P43: - | Q43: - | R43: 2026-I | S43: XIII | T43: =VLOOKUP(D43,DATA_SISTEMA!$A$1:$Q$506,9,FALSE) -> M | U43: A | V43: - | W43: 0000-00-00 | X43: U | Y43: - | Z43: - | AA43: 0000-00-00 | AB43: - | AC43: - | AD43: - | AE43: - | AF43: - | AG43: - | AH43: OR | AI43: LUIS GUSTAVO | AJ43: VELA | AK43: REQUEJO | AL43: 46445208 | AM43: - | AN43: - | AO43: - | AP43: - | AQ43: - | AR43: - | AS43: - | AT43: - | AU43: - | AV43: =VLOOKUP(D43,DATA_SISTEMA!$A$1:$Q$506,12,FALSE) -> CHICLAYO | AW43: =VLOOKUP(D43,DATA_SISTEMA!$A$1:$Q$506,11,FALSE) -> CHICLAYO | AX43: =VLOOKUP(D43,DATA_SISTEMA!$A$1:$Q$506,10,FALSE) -> LAMBAYEQUE | AY43: - | AZ43: 0000-00-00 | BA43: - | BB43: 0000-00-00 | BC43: - | BD43: 0000-00-00 | BE43: - | BF43: @UNPRG.EDU.PE | BG43: 80.5
A44: 43 | B44: AL | C44: ARCE GARCIA, BAYRON EDINSON | D44: 70382269 | E44: ING.BAYRONARCE@GMAIL.COM | F44: - | G44: 906607662 | H44: =VLOOKUP(D44,DATA_SISTEMA!$A$1:$Q$506,13,FALSE) -> JIRON SANTA ROSA 310 | I44: =VLOOKUP(D44,DATA_SISTEMA!$A$1:$Q$506,7,FALSE) -> 1995-10-25 | J44: - | K44: - | L44: - | M44: 26 | N44: 0 | O44: =_xlfn.CONCAT(A44,"0020261X") -> 430020261X | P44: - | Q44: - | R44: 2026-I | S44: XIII | T44: =VLOOKUP(D44,DATA_SISTEMA!$A$1:$Q$506,9,FALSE) -> M | U44: A | V44: - | W44: 0000-00-00 | X44: U | Y44: - | Z44: - | AA44: 0000-00-00 | AB44: - | AC44: - | AD44: - | AE44: - | AF44: - | AG44: - | AH44: OR | AI44: BAYRON EDINSON | AJ44: ARCE | AK44: GARCIA | AL44: 70382269 | AM44: - | AN44: - | AO44: - | AP44: - | AQ44: - | AR44: - | AS44: - | AT44: - | AU44: - | AV44: =VLOOKUP(D44,DATA_SISTEMA!$A$1:$Q$506,12,FALSE) -> SANTA CRUZ | AW44: =VLOOKUP(D44,DATA_SISTEMA!$A$1:$Q$506,11,FALSE) -> SANTA CRUZ | AX44: =VLOOKUP(D44,DATA_SISTEMA!$A$1:$Q$506,10,FALSE) -> CAJAMARCA | AY44: - | AZ44: 0000-00-00 | BA44: - | BB44: 0000-00-00 | BC44: - | BD44: 0000-00-00 | BE44: - | BF44: @UNPRG.EDU.PE | BG44: 77.5
... A168: 167 | B168: AL | C168: CHINCHAYAN BARRENECHEA, MARIO JESUS | D168: 73262781 | E168: mariojcb1910@gmail.com | F168: - | G168: 910201305 | H168: =VLOOKUP(D168,DATA_SISTEMA!$A$1:$Q$506,13,FALSE) -> CALLE SAN MARTIN N° 616 | I168: =VLOOKUP(D168,DATA_SISTEMA!$A$1:$Q$506,7,FALSE) -> 1992-10-19 | J168: - | K168: - | L168: - | M168: 318 | N168: 0 | O168: =_xlfn.CONCAT(A168,"0020261X") -> 1670020261X | P168: - | Q168: - | R168: 2026-I | S168: III | T168: =VLOOKUP(D168,DATA_SISTEMA!$A$1:$Q$506,9,FALSE) -> M | U168: A | V168: - | W168: 0000-00-00 | X168: U | Y168: - | Z168: - | AA168: 0000-00-00 | AB168: - | AC168: - | AD168: - | AE168: - | AF168: - | AG168: - | AH168: OR | AI168: MARIO JESUS | AJ168: CHINCHAYAN | AK168: BARRENECHEA | AL168: 73262781 | AM168: - | AN168: - | AO168: - | AP168: - | AQ168: - | AR168: - | AS168: - | AT168: - | AU168: - | AV168: =VLOOKUP(D168,DATA_SISTEMA!$A$1:$Q$506,12,FALSE) -> LAMBAYEQUE | AW168: =VLOOKUP(D168,DATA_SISTEMA!$A$1:$Q$506,11,FALSE) -> LAMBAYEQUE | AX168: =VLOOKUP(D168,DATA_SISTEMA!$A$1:$Q$506,10,FALSE) -> LAMBAYEQUE | AY168: - | AZ168: 0000-00-00 | BA168: - | BB168: 0000-00-00 | BC168: - | BD168: 0000-00-00 | BE168: - | BF168: @UNPRG.EDU.PE | BG168: 71.9
A169: 168 | B169: AL | C169: VELASQUEZ SAAVEDRA, ROGER JAVIER | D169: 3886801 | E169: rogervelasquezsaavedra@gmail.com | F169: - | G169: 947495718 | H169: =VLOOKUP(D169,DATA_SISTEMA!$A$1:$Q$506,13,FALSE) -> CONDOMINIOS LOS PARQUES DE SAN GABRIEL - DPTO.501- TORRE 31 | I169: =VLOOKUP(D169,DATA_SISTEMA!$A$1:$Q$506,7,FALSE) -> 1973-08-22 | J169: - | K169: - | L169: - | M169: 318 | N169: 0 | O169: =_xlfn.CONCAT(A169,"0020261X") -> 1680020261X | P169: - | Q169: - | R169: 2026-I | S169: III | T169: =VLOOKUP(D169,DATA_SISTEMA!$A$1:$Q$506,9,FALSE) -> M | U169: A | V169: - | W169: 0000-00-00 | X169: U | Y169: - | Z169: - | AA169: 0000-00-00 | AB169: - | AC169: - | AD169: - | AE169: - | AF169: - | AG169: - | AH169: OR | AI169: ROGER JAVIER | AJ169: VELASQUEZ | AK169: SAAVEDRA | AL169: 03886801 | AM169: - | AN169: - | AO169: - | AP169: - | AQ169: - | AR169: - | AS169: - | AT169: - | AU169: - | AV169: =VLOOKUP(D169,DATA_SISTEMA!$A$1:$Q$506,12,FALSE) -> CHICLAYO | AW169: =VLOOKUP(D169,DATA_SISTEMA!$A$1:$Q$506,11,FALSE) -> CHICLAYO | AX169: =VLOOKUP(D169,DATA_SISTEMA!$A$1:$Q$506,10,FALSE) -> LAMBAYEQUE | AY169: - | AZ169: 0000-00-00 | BA169: - | BB169: 0000-00-00 | BC169: - | BD169: 0000-00-00 | BE169: - | BF169: @UNPRG.EDU.PE | BG169: 71.9
A170: 169 | B170: AL | C170: SAAVEDRA AGUILAR, RAUL CRISTHIAN | D170: 47248891 | E170: raulcristhians@gmail.com | F170: - | G170: 940115835 | H170: =VLOOKUP(D170,DATA_SISTEMA!$A$1:$Q$506,13,FALSE) -> AV. BALTA 1793 - CHICLAYO | I170: =VLOOKUP(D170,DATA_SISTEMA!$A$1:$Q$506,7,FALSE) -> 1992-09-03 | J170: - | K170: - | L170: - | M170: 318 | N170: 0 | O170: =_xlfn.CONCAT(A170,"0020261X") -> 1690020261X | P170: - | Q170: - | R170: 2026-I | S170: III | T170: =VLOOKUP(D170,DATA_SISTEMA!$A$1:$Q$506,9,FALSE) -> M | U170: A | V170: - | W170: 0000-00-00 | X170: U | Y170: - | Z170: - | AA170: 0000-00-00 | AB170: - | AC170: - | AD170: - | AE170: - | AF170: - | AG170: - | AH170: OR | AI170: RAUL CRISTHIAN | AJ170: SAAVEDRA | AK170: AGUILAR | AL170: 47248891 | AM170: - | AN170: - | AO170: - | AP170: - | AQ170: - | AR170: - | AS170: - | AT170: - | AU170: - | AV170: =VLOOKUP(D170,DATA_SISTEMA!$A$1:$Q$506,12,FALSE) -> CHICLAYO | AW170: =VLOOKUP(D170,DATA_SISTEMA!$A$1:$Q$506,11,FALSE) -> CHICLAYO | AX170: =VLOOKUP(D170,DATA_SISTEMA!$A$1:$Q$506,10,FALSE) -> LAMBAYEQUE | AY170: - | AZ170: 0000-00-00 | BA170: - | BB170: 0000-00-00 | BC170: - | BD170: 0000-00-00 | BE170: - | BF170: @UNPRG.EDU.PE | BG170: 71
A171: 170 | B171: AL | C171: ASALDE YUPTON, MIGUEL ANGEL | D171: 43984489 | E171: masalde@unprg.edu.pe | F171: - | G171: 928228502 | H171: =VLOOKUP(D171,DATA_SISTEMA!$A$1:$Q$506,13,FALSE) -> BACA MATTOS 602 - URBANZACION MIRAFLORES | I171: =VLOOKUP(D171,DATA_SISTEMA!$A$1:$Q$506,7,FALSE) -> 1986-05-02 | J171: - | K171: - | L171: - | M171: 318 | N171: 0 | O171: =_xlfn.CONCAT(A171,"0020261X") -> 1700020261X | P171: - | Q171: - | R171: 2026-I | S171: III | T171: =VLOOKUP(D171,DATA_SISTEMA!$A$1:$Q$506,9,FALSE) -> M | U171: A | V171: - | W171: 0000-00-00 | X171: U | Y171: - | Z171: - | AA171: 0000-00-00 | AB171: - | AC171: - | AD171: - | AE171: - | AF171: - | AG171: - | AH171: OR | AI171: MIGUEL ANGEL | AJ171: ASALDE | AK171: YUPTON | AL171: 43984489 | AM171: - | AN171: - | AO171: - | AP171: - | AQ171: - | AR171: - | AS171: - | AT171: - | AU171: - | AV171: =VLOOKUP(D171,DATA_SISTEMA!$A$1:$Q$506,12,FALSE) -> LAMBAYEQUE | AW171: =VLOOKUP(D171,DATA_SISTEMA!$A$1:$Q$506,11,FALSE) -> LAMBAYEQUE | AX171: =VLOOKUP(D171,DATA_SISTEMA!$A$1:$Q$506,10,FALSE) -> LAMBAYEQUE | AY171: - | AZ171: 0000-00-00 | BA171: - | BB171: 0000-00-00 | BC171: - | BD171: 0000-00-00 | BE171: - | BF171: @UNPRG.EDU.PE | BG171: 70.5
A172: 171 | B172: AL | C172: CHUMIOQUE CHARCAPE, MYRIAN JESUS | D172: 71077059 | E172: miriam04leo@gmail.com | F172: - | G172: 936794282 | H172: =VLOOKUP(D172,DATA_SISTEMA!$A$1:$Q$506,13,FALSE) -> JR. SAN MARTIN 568 MIRAFLORES ALTO 568 | I172: =VLOOKUP(D172,DATA_SISTEMA!$A$1:$Q$506,7,FALSE) -> 2000-08-04 | J172: - | K172: - | L172: - | M172: 318 | N172: 0 | O172: =_xlfn.CONCAT(A172,"0020261X") -> 1710020261X | P172: - | Q172: - | R172: 2026-I | S172: III | T172: =VLOOKUP(D172,DATA_SISTEMA!$A$1:$Q$506,9,FALSE) -> F | U172: A | V172: - | W172: 0000-00-00 | X172: U | Y172: - | Z172: - | AA172: 0000-00-00 | AB172: - | AC172: - | AD172: - | AE172: - | AF172: - | AG172: - | AH172: OR | AI172: MYRIAN JESUS | AJ172: CHUMIOQUE | AK172: CHARCAPE | AL172: 71077059 | AM172: - | AN172: - | AO172: - | AP172: - | AQ172: - | AR172: - | AS172: - | AT172: - | AU172: - | AV172: =VLOOKUP(D172,DATA_SISTEMA!$A$1:$Q$506,12,FALSE) -> CHIMBOTE | AW172: =VLOOKUP(D172,DATA_SISTEMA!$A$1:$Q$506,11,FALSE) -> SANTA | AX172: =VLOOKUP(D172,DATA_SISTEMA!$A$1:$Q$506,10,FALSE) -> ANCASH | AY172: - | AZ172: 0000-00-00 | BA172: - | BB172: 0000-00-00 | BC172: - | BD172: 0000-00-00 | BE172: - | BF172: @UNPRG.EDU.PE | BG172: 69.9
